Workbook
Name UPDATE: 'Data Sheet'!$E$1

Sheet Profit & Loss
A1: ='Data Sheet'!B1 | H1: =UPDATE | M1: SCREENER.IN
A3: Narration | B3: ='Data Sheet'!B16 -> 0 | C3: ='Data Sheet'!C16 -> 0 | D3: ='Data Sheet'!D16 -> 0 | E3: ='Data Sheet'!E16 -> 0 | F3: ='Data Sheet'!F16 -> 0 | G3: ='Data Sheet'!G16 -> 44286 | H3: ='Data Sheet'!H16 -> 44651 | I3: ='Data Sheet'!I16 -> 45016 | ... K3: ='Data Sheet'!K16 -> 45747 | L3: Trailing | M3: Best Case | N3: Worst Case
A4: Sales | B4: ='Data Sheet'!B17 -> 0 | C4: ='Data Sheet'!C17 -> 0 | D4: ='Data Sheet'!D17 -> 0 | E4: ='Data Sheet'!E17 -> 0 | F4: ='Data Sheet'!F17 -> 0 | G4: ='Data Sheet'!G17 -> 459.99 | H4: ='Data Sheet'!H17 -> 943.47 | I4: ='Data Sheet'!I17 -> 1492.75 | ... K4: ='Data Sheet'!K17 -> 2066.95 | L4: =SUM(Quarters!H4:K4) -> 2268.41 | M4: =$K4+M23*K4 -> 2684.5032 | N4: =$K4+N23*L4 -> 2288.0458
A5: Expenses | B5: =SUM('Data Sheet'!B18,'Data Sheet'!B20:B24,-1*'Data Sheet'!B19) -> 0 | C5: =SUM('Data Sheet'!C18,'Data Sheet'!C20:C24,-1*'Data Sheet'!C19) -> 0 | D5: =SUM('Data Sheet'!D18,'Data Sheet'!D20:D24,-1*'Data Sheet'!D19) -> 0 | E5: =SUM('Data Sheet'!E18,'Data Sheet'!E20:E24,-1*'Data Sheet'!E19) -> 0 | F5: =SUM('Data Sheet'!F18,'Data Sheet'!F20:F24,-1*'Data Sheet'!F19) -> 0 | G5: =SUM('Data Sheet'!G18,'Data Sheet'!G20:G24,-1*'Data Sheet'!G19) -> 1794.01 | H5: =SUM('Data Sheet'!H18,'Data Sheet'!H20:H24,-1*'Data Sheet'!H19) -> 931.97 | I5: =SUM('Data Sheet'!I18,'Data Sheet'!I20:I24,-1*'Data Sheet'!I19) -> 1469.99 | ... K5: =SUM('Data Sheet'!K18,'Data Sheet'!K20:K24,-1*'Data Sheet'!K19) -> 1998.41 | L5: =SUM(Quarters!H5:K5) -> 2082.5 | M5: =M4-M6 -> 2464.4919 | N5: =N4-N6 -> 2207.9233
A6: Operating Profit | B6: =B4-B5 -> 0 | C6: =C4-C5 -> 0 | D6: =D4-D5 -> 0 | E6: =E4-E5 -> 0 | F6: =F4-F5 -> 0 | G6: =G4-G5 -> -1334.02 | H6: =H4-H5 -> 11.5 | I6: =I4-I5 -> 22.76 | ... K6: =K4-K5 -> 68.54 | L6: =SUM(Quarters!H6:K6) -> 185.91 | M6: =M4*M24 -> 220.01137 | N6: =N4*N24 -> 80.122456
A7: Other Income | B7: ='Data Sheet'!B25 -> 0 | C7: ='Data Sheet'!C25 -> 0 | D7: ='Data Sheet'!D25 -> 0 | E7: ='Data Sheet'!E25 -> 0 | F7: ='Data Sheet'!F25 -> 0 | G7: ='Data Sheet'!G25 -> 12.1 | H7: ='Data Sheet'!H25 -> 20.84 | I7: ='Data Sheet'!I25 -> -132.18 | ... K7: ='Data Sheet'!K25 -> 78.73 | L7: =SUM(Quarters!H7:K7) -> 80.69 | M7: 0 | N7: 0
A8: Depreciation | B8: ='Data Sheet'!B26 -> 0 | C8: ='Data Sheet'!C26 -> 0 | D8: ='Data Sheet'!D26 -> 0 | E8: ='Data Sheet'!E26 -> 0 | F8: ='Data Sheet'!F26 -> 0 | G8: ='Data Sheet'!G26 -> 1.71 | H8: ='Data Sheet'!H26 -> 6.9 | I8: ='Data Sheet'!I26 -> 24.96 | ... K8: ='Data Sheet'!K26 -> 45.01 | L8: =SUM(Quarters!H8:K8) -> 46.02 | M8: =+$L8 -> 46.02 | N8: =+$L8 -> 46.02
A9: Interest | B9: ='Data Sheet'!B27 -> 0 | C9: ='Data Sheet'!C27 -> 0 | D9: ='Data Sheet'!D27 -> 0 | E9: ='Data Sheet'!E27 -> 0 | F9: ='Data Sheet'!F27 -> 0 | G9: ='Data Sheet'!G27 -> 0.98 | H9: ='Data Sheet'!H27 -> 3.01 | I9: ='Data Sheet'!I27 -> 6.66 | ... K9: ='Data Sheet'!K27 -> 12.65 | L9: =SUM(Quarters!H9:K9) -> 12.98 | M9: =+$L9 -> 12.98 | N9: =+$L9 -> 12.98
A10: Profit before tax | B10: ='Data Sheet'!B28 -> 0 | C10: ='Data Sheet'!C28 -> 0 | D10: ='Data Sheet'!D28 -> 0 | E10: ='Data Sheet'!E28 -> 0 | F10: ='Data Sheet'!F28 -> 0 | G10: ='Data Sheet'!G28 -> -1324.61 | H10: ='Data Sheet'!H28 -> 22.43 | I10: ='Data Sheet'!I28 -> -141.04 | ... K10: ='Data Sheet'!K28 -> 89.61 | L10: =SUM(Quarters!H10:K10) -> 207.6 | M10: =M6+M7-SUM(M8:M9) -> 161.01137 | N10: =N6+N7-SUM(N8:N9) -> 21.122456
A11: Tax | B11: ='Data Sheet'!B29 -> 0 | C11: ='Data Sheet'!C29 -> 0 | D11: ='Data Sheet'!D29 -> 0 | E11: ='Data Sheet'!E29 -> 0 | F11: ='Data Sheet'!F29 -> 0 | G11: ='Data Sheet'!G29 -> 7.61 | H11: ='Data Sheet'!H29 -> 8 | I11: ='Data Sheet'!I29 -> 9.93 | ... K11: ='Data Sheet'!K29 -> 16.93 | L11: =SUM(Quarters!H11:K11) -> 51.86 | M11: =IF($L10>0,$L11/$L10,0) -> 0.24980732 | N11: =IF($L10>0,$L11/$L10,0) -> 0.24980732
A12: Net profit | B12: ='Data Sheet'!B30 -> 0 | C12: ='Data Sheet'!C30 -> 0 | D12: ='Data Sheet'!D30 -> 0 | E12: ='Data Sheet'!E30 -> 0 | F12: ='Data Sheet'!F30 -> 0 | G12: ='Data Sheet'!G30 -> -1332.22 | H12: ='Data Sheet'!H30 -> 15.72 | I12: ='Data Sheet'!I30 -> -142.81 | ... K12: ='Data Sheet'!K30 -> 72.69 | L12: =SUM(Quarters!H12:K12) -> 155.74 | M12: =M10-M11*M10 -> 120.78955 | N12: =N10-N11*N10 -> 15.845912
A13: EPS | B13: =IF('Data Sheet'!B93>0,B12/'Data Sheet'!B93,0) -> 0 | C13: =IF('Data Sheet'!C93>0,C12/'Data Sheet'!C93,0) -> 0 | D13: =IF('Data Sheet'!D93>0,D12/'Data Sheet'!D93,0) -> 0 | E13: =IF('Data Sheet'!E93>0,E12/'Data Sheet'!E93,0) -> 0 | F13: =IF('Data Sheet'!F93>0,F12/'Data Sheet'!F93,0) -> 0 | G13: =IF('Data Sheet'!G93>0,G12/'Data Sheet'!G93,0) -> -1266971 | H13: =IF('Data Sheet'!H93>0,H12/'Data Sheet'!H93,0) -> 14906.126 | I13: =IF('Data Sheet'!I93>0,I12/'Data Sheet'!I93,0) -> -10.477623 | ... K13: =IF('Data Sheet'!K93>0,K12/'Data Sheet'!K93,0) -> 2.2352399 | L13: =IF('Data Sheet'!$B6>0,'Profit & Loss'!L12/'Data Sheet'!$B6,0) -> 4.7865517 | M13: =IF('Data Sheet'!$B6>0,'Profit & Loss'!M12/'Data Sheet'!$B6,0) -> 3.712376 | N13: =IF('Data Sheet'!$B6>0,'Profit & Loss'!N12/'Data Sheet'!$B6,0) -> 0.48701217
A14: Price to earning | B14: =IF(B15>0,B15/B13,"") | C14: =IF(C15>0,C15/C13,"") | D14: =IF(D15>0,D15/D13,"") | E14: =IF(E15>0,E15/E13,"") | F14: =IF(F15>0,F15/F13,"") | G14: =IF(G15>0,G15/G13,"") | H14: =IF(H15>0,H15/H13,"") | I14: =IF(I15>0,I15/I13,"") | ... K14: =IF(K15>0,K15/K13,"") -> 103.72936 | L14: =IF(L13>0,L15/L13,0) -> 72.881276 | M14: =M25 -> 97.759522 | N14: =N25 -> 72.881276
A15: Price | B15: ='Data Sheet'!B90 -> 0 | C15: ='Data Sheet'!C90 -> 0 | D15: ='Data Sheet'!D90 -> 0 | E15: ='Data Sheet'!E90 -> 0 | F15: ='Data Sheet'!F90 -> 0 | G15: ='Data Sheet'!G90 -> 0 | H15: ='Data Sheet'!H90 -> 0 | I15: ='Data Sheet'!I90 -> 0 | ... K15: ='Data Sheet'!K90 -> 231.86 | L15: ='Data Sheet'!B8 -> 348.85 | M15: =M13*M14 -> 362.9201 | N15: =N13*N14 -> 35.494069
A17: RATIOS:
A18: Dividend Payout | B18: =IF('Data Sheet'!B30>0,'Data Sheet'!B31/'Data Sheet'!B30,0) -> 0 | C18: =IF('Data Sheet'!C30>0,'Data Sheet'!C31/'Data Sheet'!C30,0) -> 0 | D18: =IF('Data Sheet'!D30>0,'Data Sheet'!D31/'Data Sheet'!D30,0) -> 0 | E18: =IF('Data Sheet'!E30>0,'Data Sheet'!E31/'Data Sheet'!E30,0) -> 0 | F18: =IF('Data Sheet'!F30>0,'Data Sheet'!F31/'Data Sheet'!F30,0) -> 0 | G18: =IF('Data Sheet'!G30>0,'Data Sheet'!G31/'Data Sheet'!G30,0) -> 0 | H18: =IF('Data Sheet'!H30>0,'Data Sheet'!H31/'Data Sheet'!H30,0) -> 0 | I18: =IF('Data Sheet'!I30>0,'Data Sheet'!I31/'Data Sheet'!I30,0) -> 0 | ... K18: =IF('Data Sheet'!K30>0,'Data Sheet'!K31/'Data Sheet'!K30,0) -> 0
A19: OPM | B19: =IF(B6>0,B6/B4,0) -> 0 | C19: =IF(C6>0,C6/C4,0) -> 0 | D19: =IF(D6>0,D6/D4,0) -> 0 | E19: =IF(E6>0,E6/E4,0) -> 0 | F19: =IF(F6>0,F6/F4,0) -> 0 | G19: =IF(G6>0,G6/G4,0) -> 0 | H19: =IF(H6>0,H6/H4,0) -> 0.012189047 | I19: =IF(I6>0,I6/I4,0) -> 0.015247027 | ... L19: =IF(L6>0,L6/L4,0) -> 0.081956084
G22: TRENDS: | H22: 10 YEARS | I22: 7 YEARS | J22: 5 YEARS | K22: 3 YEARS | L22: RECENT | M22: BEST | N22: WORST
G23: Sales Growth | H23: =IF(B4=0,"",POWER($K4/B4,1/9)-1) | I23: =IF(D4=0,"",POWER($K4/D4,1/7)-1) | J23: =IF(F4=0,"",POWER($K4/F4,1/5)-1) | K23: =IF(H4=0,"",POWER($K4/H4,1/3)-1) -> 0.29877511 | L23: =IF(ISERROR(MAX(IF(J4=0,"",(K4-J4)/J4),IF(K4=0,"",(L4-K4)/K4))),"",MAX(IF(J4=0,"",(K4-J4)/J4),IF(K4=0,"",(L4-K4)/K4))) -> 0.097467283 | M23: =MAX(K23:L23) -> 0.29877511 | N23: =MIN(H23:L23) -> 0.097467283
G24: OPM | H24: =IF(SUM(B4:$K$4)=0,"",SUMPRODUCT(B19:$K$19,B4:$K$4)/SUM(B4:$K$4)) -> 0.035017855 | I24: =IF(SUM(E4:$K$4)=0,"",SUMPRODUCT(E19:$K$19,E4:$K$4)/SUM(E4:$K$4)) -> 0.035017855 | J24: =IF(SUM(G4:$K$4)=0,"",SUMPRODUCT(G19:$K$19,G4:$K$4)/SUM(G4:$K$4)) -> 0.035017855 | K24: =IF(SUM(I4:$K$4)=0,"",SUMPRODUCT(I19:$K$19,I4:$K$4)/SUM(I4:$K$4)) -> 0.041888094 | L24: =L19 -> 0.081956084 | M24: =MAX(K24:L24) -> 0.081956084 | N24: =MIN(H24:L24) -> 0.035017855
G25: Price to Earning | H25: =IF(ISERROR(AVERAGEIF(B14:$L14,">0")),"",AVERAGEIF(B14:$L14,">0")) -> 97.759522 | I25: =IF(ISERROR(AVERAGEIF(E14:$L14,">0")),"",AVERAGEIF(E14:$L14,">0")) -> 97.759522 | J25: =IF(ISERROR(AVERAGEIF(G14:$L14,">0")),"",AVERAGEIF(G14:$L14,">0")) -> 97.759522 | K25: =IF(ISERROR(AVERAGEIF(I14:$L14,">0")),"",AVERAGEIF(I14:$L14,">0")) -> 97.759522 | L25: =L14 -> 72.881276 | M25: =MAX(K25:L25) -> 97.759522 | N25: =MIN(H25:L25) -> 72.881276

Sheet Quarters
A1: ='Profit & Loss'!A1 | E1: =UPDATE | J1: SCREENER.IN
A3: Narration | B3: ='Data Sheet'!B41 -> 45199 | C3: ='Data Sheet'!C41 -> 45291 | D3: ='Data Sheet'!D41 -> 45382 | E3: ='Data Sheet'!E41 -> 45473 | F3: ='Data Sheet'!F41 -> 45565 | G3: ='Data Sheet'!G41 -> 45657 | H3: ='Data Sheet'!H41 -> 45747 | I3: ='Data Sheet'!I41 -> 45838 | ... K3: ='Data Sheet'!K41 -> 46022
A4: Sales | B4: ='Data Sheet'!B42 -> 496.11 | C4: ='Data Sheet'!C42 -> 488.22 | D4: ='Data Sheet'!D42 -> 471.09 | E4: ='Data Sheet'!E42 -> 554.06 | F4: ='Data Sheet'!F42 -> 461.82 | G4: ='Data Sheet'!G42 -> 517.51 | H4: ='Data Sheet'!H42 -> 533.56 | I4: ='Data Sheet'!I42 -> 595.25 | ... K4: ='Data Sheet'!K42 -> 601.54
A5: Expenses | B5: ='Data Sheet'!B43 -> 455.9 | C5: ='Data Sheet'!C43 -> 453.77 | D5: ='Data Sheet'!D43 -> 437.97 | E5: ='Data Sheet'!E43 -> 507.94 | F5: ='Data Sheet'!F43 -> 492.52 | G5: ='Data Sheet'!G43 -> 491.38 | H5: ='Data Sheet'!H43 -> 506.58 | I5: ='Data Sheet'!I43 -> 549.45 | ... K5: ='Data Sheet'!K43 -> 536.06
A6: Operating Profit | B6: ='Data Sheet'!B50 -> 40.21 | C6: ='Data Sheet'!C50 -> 34.45 | D6: ='Data Sheet'!D50 -> 33.12 | E6: ='Data Sheet'!E50 -> 46.12 | F6: ='Data Sheet'!F50 -> -30.7 | G6: ='Data Sheet'!G50 -> 26.13 | H6: ='Data Sheet'!H50 -> 26.98 | I6: ='Data Sheet'!I50 -> 45.8 | ... K6: ='Data Sheet'!K50 -> 65.48
A7: Other Income | B7: ='Data Sheet'!B44 -> 7.08 | C7: ='Data Sheet'!C44 -> 10.97 | D7: ='Data Sheet'!D44 -> 19.05 | E7: ='Data Sheet'!E44 -> 18.72 | F7: ='Data Sheet'!F44 -> 20.02 | G7: ='Data Sheet'!G44 -> 19.22 | H7: ='Data Sheet'!H44 -> 20.78 | I7: ='Data Sheet'!I44 -> 23.89 | ... K7: ='Data Sheet'!K44 -> 15.88
A8: Depreciation | B8: ='Data Sheet'!B45 -> 6.29 | C8: ='Data Sheet'!C45 -> 8.06 | D8: ='Data Sheet'!D45 -> 9.78 | E8: ='Data Sheet'!E45 -> 9.42 | F8: ='Data Sheet'!F45 -> 10.56 | G8: ='Data Sheet'!G45 -> 12.61 | H8: ='Data Sheet'!H45 -> 12.42 | I8: ='Data Sheet'!I45 -> 10.82 | ... K8: ='Data Sheet'!K45 -> 11.04
A9: Interest | B9: ='Data Sheet'!B46 -> 1.79 | C9: ='Data Sheet'!C46 -> 2.64 | D9: ='Data Sheet'!D46 -> 3.14 | E9: ='Data Sheet'!E46 -> 3.03 | F9: ='Data Sheet'!F46 -> 3.13 | G9: ='Data Sheet'!G46 -> 3.32 | H9: ='Data Sheet'!H46 -> 3.17 | I9: ='Data Sheet'!I46 -> 3.28 | ... K9: ='Data Sheet'!K46 -> 3.23
A10: Profit before tax | B10: ='Data Sheet'!B47 -> 39.21 | C10: ='Data Sheet'!C47 -> 34.72 | D10: ='Data Sheet'!D47 -> 39.25 | E10: ='Data Sheet'!E47 -> 52.39 | F10: ='Data Sheet'!F47 -> -24.37 | G10: ='Data Sheet'!G47 -> 29.42 | H10: ='Data Sheet'!H47 -> 32.17 | I10: ='Data Sheet'!I47 -> 55.59 | ... K10: ='Data Sheet'!K47 -> 67.09
A11: Tax | B11: ='Data Sheet'!B48 -> 9.77 | C11: ='Data Sheet'!C48 -> 8.82 | D11: ='Data Sheet'!D48 -> 8.78 | E11: ='Data Sheet'!E48 -> 12.13 | F11: ='Data Sheet'!F48 -> -5.8 | G11: ='Data Sheet'!G48 -> 3.39 | H11: ='Data Sheet'!H48 -> 7.19 | I11: ='Data Sheet'!I48 -> 14.27 | ... K11: ='Data Sheet'!K48 -> 16.88
A12: Net profit | B12: ='Data Sheet'!B49 -> 29.44 | C12: ='Data Sheet'!C49 -> 25.9 | D12: ='Data Sheet'!D49 -> 30.48 | E12: ='Data Sheet'!E49 -> 40.26 | F12: ='Data Sheet'!F49 -> -18.58 | G12: ='Data Sheet'!G49 -> 26.02 | H12: ='Data Sheet'!H49 -> 24.98 | I12: ='Data Sheet'!I49 -> 41.33 | ... K12: ='Data Sheet'!K49 -> 50.2
A14: OPM | B14: =IF(B4>0,B6/B4,"") -> 0.081050573 | C14: =IF(C4>0,C6/C4,"") -> 0.070562451 | D14: =IF(D4>0,D6/D4,"") -> 0.070305037 | E14: =IF(E4>0,E6/E4,"") -> 0.083240082 | F14: =IF(F4>0,F6/F4,"") -> -0.066476116 | G14: =IF(G4>0,G6/G4,"") -> 0.050491778 | H14: =IF(H4>0,H6/H4,"") -> 0.050566009 | I14: =IF(I4>0,I6/I4,"") -> 0.076942461 | ... K14: =IF(K4>0,K6/K4,"") -> 0.10885394

Sheet Balance Sheet
A1: ='Profit & Loss'!A1 | E1: =UPDATE | J1: SCREENER.IN
A3: Narration | B3: ='Data Sheet'!B56 -> 0 | C3: ='Data Sheet'!C56 -> 0 | D3: ='Data Sheet'!D56 -> 0 | E3: ='Data Sheet'!E56 -> 0 | F3: ='Data Sheet'!F56 -> 0 | G3: ='Data Sheet'!G56 -> 44286 | H3: ='Data Sheet'!H56 -> 44651 | I3: ='Data Sheet'!I56 -> 45016 | ... K3: ='Data Sheet'!K56 -> 45747
A4: Equity Share Capital | B4: ='Data Sheet'!B57 -> 0 | C4: ='Data Sheet'!C57 -> 0 | D4: ='Data Sheet'!D57 -> 0 | E4: ='Data Sheet'!E57 -> 0 | F4: ='Data Sheet'!F57 -> 0 | G4: ='Data Sheet'!G57 -> 0.01 | H4: ='Data Sheet'!H57 -> 0.01 | I4: ='Data Sheet'!I57 -> 136.34 | ... K4: ='Data Sheet'!K57 -> 325.18
A5: Reserves | B5: ='Data Sheet'!B58 -> 0 | C5: ='Data Sheet'!C58 -> 0 | D5: ='Data Sheet'!D58 -> 0 | E5: ='Data Sheet'!E58 -> 0 | F5: ='Data Sheet'!F58 -> 0 | G5: ='Data Sheet'!G58 -> -1765.17 | H5: ='Data Sheet'!H58 -> -1087.33 | I5: ='Data Sheet'!I58 -> -1323.37 | ... K5: ='Data Sheet'!K58 -> 854.65
A6: Borrowings | B6: ='Data Sheet'!B59 -> 0 | C6: ='Data Sheet'!C59 -> 0 | D6: ='Data Sheet'!D59 -> 0 | E6: ='Data Sheet'!E59 -> 0 | F6: ='Data Sheet'!F59 -> 0 | G6: ='Data Sheet'!G59 -> 1954.01 | H6: ='Data Sheet'!H59 -> 1852.57 | I6: ='Data Sheet'!I59 -> 1885.13 | ... K6: ='Data Sheet'!K59 -> 136.4
A7: Other Liabilities | B7: ='Data Sheet'!B60 -> 0 | C7: ='Data Sheet'!C60 -> 0 | D7: ='Data Sheet'!D60 -> 0 | E7: ='Data Sheet'!E60 -> 0 | F7: ='Data Sheet'!F60 -> 0 | G7: ='Data Sheet'!G60 -> 113.79 | H7: ='Data Sheet'!H60 -> 271.05 | I7: ='Data Sheet'!I60 -> 278.23 | ... K7: ='Data Sheet'!K60 -> 491.95
A8: Total | B8: ='Data Sheet'!B61 -> 0 | C8: ='Data Sheet'!C61 -> 0 | D8: ='Data Sheet'!D61 -> 0 | E8: ='Data Sheet'!E61 -> 0 | F8: ='Data Sheet'!F61 -> 0 | G8: ='Data Sheet'!G61 -> 302.64 | H8: ='Data Sheet'!H61 -> 1036.3 | I8: ='Data Sheet'!I61 -> 976.33 | ... K8: ='Data Sheet'!K61 -> 1808.18
A10: Net Block | B10: ='Data Sheet'!B62 -> 0 | C10: ='Data Sheet'!C62 -> 0 | D10: ='Data Sheet'!D62 -> 0 | E10: ='Data Sheet'!E62 -> 0 | F10: ='Data Sheet'!F62 -> 0 | G10: ='Data Sheet'!G62 -> 21.09 | H10: ='Data Sheet'!H62 -> 341.6 | I10: ='Data Sheet'!I62 -> 252.46 | ... K10: ='Data Sheet'!K62 -> 302.18
A11: Capital Work in Progress | B11: ='Data Sheet'!B63 -> 0 | C11: ='Data Sheet'!C63 -> 0 | D11: ='Data Sheet'!D63 -> 0 | E11: ='Data Sheet'!E63 -> 0 | F11: ='Data Sheet'!F63 -> 0 | G11: ='Data Sheet'!G63 -> 0 | H11: ='Data Sheet'!H63 -> 1.88 | I11: ='Data Sheet'!I63 -> 0 | ... K11: ='Data Sheet'!K63 -> 0.08
A12: Investments | B12: ='Data Sheet'!B64 -> 0 | C12: ='Data Sheet'!C64 -> 0 | D12: ='Data Sheet'!D64 -> 0 | E12: ='Data Sheet'!E64 -> 0 | F12: ='Data Sheet'!F64 -> 0 | G12: ='Data Sheet'!G64 -> 164.43 | H12: ='Data Sheet'!H64 -> 338.51 | I12: ='Data Sheet'!I64 -> 260.04 | ... K12: ='Data Sheet'!K64 -> 304.78
A13: Other Assets | B13: ='Data Sheet'!B65 -> 0 | C13: ='Data Sheet'!C65 -> 0 | D13: ='Data Sheet'!D65 -> 0 | E13: ='Data Sheet'!E65 -> 0 | F13: ='Data Sheet'!F65 -> 0 | G13: ='Data Sheet'!G65 -> 117.12 | H13: ='Data Sheet'!H65 -> 354.31 | I13: ='Data Sheet'!I65 -> 463.83 | ... K13: ='Data Sheet'!K65 -> 1201.14
A14: Total | B14: ='Data Sheet'!B66 -> 0 | C14: ='Data Sheet'!C66 -> 0 | D14: ='Data Sheet'!D66 -> 0 | E14: ='Data Sheet'!E66 -> 0 | F14: ='Data Sheet'!F66 -> 0 | G14: ='Data Sheet'!G66 -> 302.64 | H14: ='Data Sheet'!H66 -> 1036.3 | I14: ='Data Sheet'!I66 -> 976.33 | ... K14: ='Data Sheet'!K66 -> 1808.18
A16: Working Capital | B16: =B13-B7 -> 0 | C16: =C13-C7 -> 0 | D16: =D13-D7 -> 0 | E16: =E13-E7 -> 0 | F16: =F13-F7 -> 0 | G16: =G13-G7 -> 3.33 | H16: =H13-H7 -> 83.26 | I16: =I13-I7 -> 185.6 | ... K16: =K13-K7 -> 709.19
A17: Debtors | B17: ='Data Sheet'!B67 -> 0 | C17: ='Data Sheet'!C67 -> 0 | D17: ='Data Sheet'!D67 -> 0 | E17: ='Data Sheet'!E67 -> 0 | F17: ='Data Sheet'!F67 -> 0 | G17: ='Data Sheet'!G67 -> 33.84 | H17: ='Data Sheet'!H67 -> 72.79 | I17: ='Data Sheet'!I67 -> 127.7 | ... K17: ='Data Sheet'!K67 -> 132.33
A18: Inventory | B18: ='Data Sheet'!B68 -> 0 | C18: ='Data Sheet'!C68 -> 0 | D18: ='Data Sheet'!D68 -> 0 | E18: ='Data Sheet'!E68 -> 0 | F18: ='Data Sheet'!F68 -> 0 | G18: ='Data Sheet'!G68 -> 41.35 | H18: ='Data Sheet'!H68 -> 67.14 | I18: ='Data Sheet'!I68 -> 123.85 | ... K18: ='Data Sheet'!K68 -> 176.32
A20: Debtor Days | B20: =IF('Profit & Loss'!B4>0,'Balance Sheet'!B17/('Profit & Loss'!B4/365),0) -> 0 | C20: =IF('Profit & Loss'!C4>0,'Balance Sheet'!C17/('Profit & Loss'!C4/365),0) -> 0 | D20: =IF('Profit & Loss'!D4>0,'Balance Sheet'!D17/('Profit & Loss'!D4/365),0) -> 0 | E20: =IF('Profit & Loss'!E4>0,'Balance Sheet'!E17/('Profit & Loss'!E4/365),0) -> 0 | F20: =IF('Profit & Loss'!F4>0,'Balance Sheet'!F17/('Profit & Loss'!F4/365),0) -> 0 | G20: =IF('Profit & Loss'!G4>0,'Balance Sheet'!G17/('Profit & Loss'!G4/365),0) -> 26.851888 | H20: =IF('Profit & Loss'!H4>0,'Balance Sheet'!H17/('Profit & Loss'!H4/365),0) -> 28.160249 | I20: =IF('Profit & Loss'!I4>0,'Balance Sheet'!I17/('Profit & Loss'!I4/365),0) -> 31.224585 | ... K20: =IF('Profit & Loss'!K4>0,'Balance Sheet'!K17/('Profit & Loss'!K4/365),0) -> 23.367982
A21: Inventory Turnover | B21: =IF('Balance Sheet'!B18>0,'Profit & Loss'!B4/'Balance Sheet'!B18,0) -> 0 | C21: =IF('Balance Sheet'!C18>0,'Profit & Loss'!C4/'Balance Sheet'!C18,0) -> 0 | D21: =IF('Balance Sheet'!D18>0,'Profit & Loss'!D4/'Balance Sheet'!D18,0) -> 0 | E21: =IF('Balance Sheet'!E18>0,'Profit & Loss'!E4/'Balance Sheet'!E18,0) -> 0 | F21: =IF('Balance Sheet'!F18>0,'Profit & Loss'!F4/'Balance Sheet'!F18,0) -> 0 | G21: =IF('Balance Sheet'!G18>0,'Profit & Loss'!G4/'Balance Sheet'!G18,0) -> 11.124305 | H21: =IF('Balance Sheet'!H18>0,'Profit & Loss'!H4/'Balance Sheet'!H18,0) -> 14.052279 | I21: =IF('Balance Sheet'!I18>0,'Profit & Loss'!I4/'Balance Sheet'!I18,0) -> 12.052887 | ... K21: =IF('Balance Sheet'!K18>0,'Profit & Loss'!K4/'Balance Sheet'!K18,0) -> 11.72272
A23: Return on Equity | B23: =IF(SUM('Balance Sheet'!B4:B5)>0,'Profit & Loss'!B12/SUM('Balance Sheet'!B4:B5),"") | C23: =IF(SUM('Balance Sheet'!C4:C5)>0,'Profit & Loss'!C12/SUM('Balance Sheet'!C4:C5),"") | D23: =IF(SUM('Balance Sheet'!D4:D5)>0,'Profit & Loss'!D12/SUM('Balance Sheet'!D4:D5),"") | E23: =IF(SUM('Balance Sheet'!E4:E5)>0,'Profit & Loss'!E12/SUM('Balance Sheet'!E4:E5),"") | F23: =IF(SUM('Balance Sheet'!F4:F5)>0,'Profit & Loss'!F12/SUM('Balance Sheet'!F4:F5),"") | G23: =IF(SUM('Balance Sheet'!G4:G5)>0,'Profit & Loss'!G12/SUM('Balance Sheet'!G4:G5),"") | H23: =IF(SUM('Balance Sheet'!H4:H5)>0,'Profit & Loss'!H12/SUM('Balance Sheet'!H4:H5),"") | I23: =IF(SUM('Balance Sheet'!I4:I5)>0,'Profit & Loss'!I12/SUM('Balance Sheet'!I4:I5),"") | ... K23: =IF(SUM('Balance Sheet'!K4:K5)>0,'Profit & Loss'!K12/SUM('Balance Sheet'!K4:K5),"") -> 0.061610571
A24: Return on Capital Emp | C24: =IF((B4+B5+B6+C4+C5+C6)>0,('Profit & Loss'!C10+'Profit & Loss'!C9)*2/(B4+B5+B6+C4+C5+C6),"") | D24: =IF((C4+C5+C6+D4+D5+D6)>0,('Profit & Loss'!D10+'Profit & Loss'!D9)*2/(C4+C5+C6+D4+D5+D6),"") | E24: =IF((D4+D5+D6+E4+E5+E6)>0,('Profit & Loss'!E10+'Profit & Loss'!E9)*2/(D4+D5+D6+E4+E5+E6),"") | F24: =IF((E4+E5+E6+F4+F5+F6)>0,('Profit & Loss'!F10+'Profit & Loss'!F9)*2/(E4+E5+E6+F4+F5+F6),"") | G24: =IF((F4+F5+F6+G4+G5+G6)>0,('Profit & Loss'!G10+'Profit & Loss'!G9)*2/(F4+F5+F6+G4+G5+G6),"") -> -14.017792 | H24: =IF((G4+G5+G6+H4+H5+H6)>0,('Profit & Loss'!H10+'Profit & Loss'!H9)*2/(G4+G5+G6+H4+H5+H6),"") -> 0.053327743 | I24: =IF((H4+H5+H6+I4+I5+I6)>0,('Profit & Loss'!I10+'Profit & Loss'!I9)*2/(H4+H5+H6+I4+I5+I6),"") -> -0.18366078 | J24: =IF((I4+I5+I6+J4+J5+J6)>0,('Profit & Loss'!J10+'Profit & Loss'!J9)*2/(I4+I5+I6+J4+J5+J6),"") -> 0.16235177 | K24: =IF((J4+J5+J6+K4+K5+K6)>0,('Profit & Loss'!K10+'Profit & Loss'!K9)*2/(J4+J5+J6+K4+K5+K6),"") -> 0.08044146

Sheet Cash Flow
A1: ='Balance Sheet'!A1 | E1: =UPDATE | J1: SCREENER.IN
A3: Narration | B3: ='Data Sheet'!B81 -> 0 | C3: ='Data Sheet'!C81 -> 0 | D3: ='Data Sheet'!D81 -> 0 | E3: ='Data Sheet'!E81 -> 0 | F3: ='Data Sheet'!F81 -> 0 | G3: ='Data Sheet'!G81 -> 44286 | H3: ='Data Sheet'!H81 -> 44651 | I3: ='Data Sheet'!I81 -> 45016 | ... K3: ='Data Sheet'!K81 -> 45747
A4: Cash from Operating Activity | B4: ='Data Sheet'!B82 -> 0 | C4: ='Data Sheet'!C82 -> 0 | D4: ='Data Sheet'!D82 -> 0 | E4: ='Data Sheet'!E82 -> 0 | F4: ='Data Sheet'!F82 -> 0 | G4: ='Data Sheet'!G82 -> 29.73 | H4: ='Data Sheet'!H82 -> 44.59 | I4: ='Data Sheet'!I82 -> -51.55 | ... K4: ='Data Sheet'!K82 -> 102.18
A5: Cash from Investing Activity | B5: ='Data Sheet'!B83 -> 0 | C5: ='Data Sheet'!C83 -> 0 | D5: ='Data Sheet'!D83 -> 0 | E5: ='Data Sheet'!E83 -> 0 | F5: ='Data Sheet'!F83 -> 0 | G5: ='Data Sheet'!G83 -> -20.61 | H5: ='Data Sheet'!H83 -> -504.76 | I5: ='Data Sheet'!I83 -> 39.87 | ... K5: ='Data Sheet'!K83 -> -145.12
A6: Cash from Financing Activity | B6: ='Data Sheet'!B84 -> 0 | C6: ='Data Sheet'!C84 -> 0 | D6: ='Data Sheet'!D84 -> 0 | E6: ='Data Sheet'!E84 -> 0 | F6: ='Data Sheet'!F84 -> 0 | G6: ='Data Sheet'!G84 -> -1.28 | H6: ='Data Sheet'!H84 -> 480.8 | I6: ='Data Sheet'!I84 -> -14.06 | ... K6: ='Data Sheet'!K84 -> -31.11
A7: Net Cash Flow | B7: ='Data Sheet'!B85 -> 0 | C7: ='Data Sheet'!C85 -> 0 | D7: ='Data Sheet'!D85 -> 0 | E7: ='Data Sheet'!E85 -> 0 | F7: ='Data Sheet'!F85 -> 0 | G7: ='Data Sheet'!G85 -> 7.84 | H7: ='Data Sheet'!H85 -> 20.63 | I7: ='Data Sheet'!I85 -> -25.74 | ... K7: ='Data Sheet'!K85 -> -74.05

Sheet Customization
A1: How to use it?
A3: You can customize this workbook as you want.
B4: You can add custom formating, add conditional formating, add your own formulas… do ANYTHING.
B5: Please don't edit the "Data Sheet" only.
A7: After customization, you can upload this back on Screener.
B8: Upload on: | C8: https://www.screener.in/excel/
A10: Download your customized workbooks now onwards.
B11: Now whenever you will "Export to excel" from Screener, it will export your customized file.
A14: TESTING:
B15: This is a testing feature currently.
B16: You can report any formula errors on the worksheet at: support@screener.in

Sheet Data Sheet
A1: COMPANY NAME | B1: HONASA CONSUMER LTD | E1: =IF(B2<>B3,"A NEW VERSION OF THE WORKSHEET IS AVAILABLE","")
A2: LATEST VERSION | B2: 2.1
A3: CURRENT VERSION | B3: 2.1
A5: META
A6: Number of shares | B6: =IF(B9>0,B9/B8,0) -> 32.536993
A7: Face Value | B7: 10
A8: Current Price | B8: 348.85
A9: Market Capitalization | B9: 11350.53
A15: PROFIT & LOSS
A16: Report Date | G16: 44286 | H16: 44651 | I16: 45016 | J16: 45382 | K16: 45747
A17: Sales | G17: 459.99 | H17: 943.47 | I17: 1492.75 | J17: 1919.9 | K17: 2066.95 | L17: Ad spend % of revenue 53%
A18: Raw Material Cost | G18: 160.78 | H18: 304.77 | I18: 502.42 | J18: 593.57 | K18: 656.39 | L18: Net profit decline -35% | M18: -0.35
A19: Change in Inventory | G19: 28.07 | H19: 21.33 | I19: 55.69 | J19: 12.88 | K19: 43.46 | L19: Revenue growth 349% | M19: =(K17-G17)/G17 -> 3.4934672
A20: Power and Fuel | G20: 0.08 | H20: 0.18 | I20: 0.84 | J20: 1.43 | K20: 2.14
A21: Other Mfr. Exp | G21: 54.71 | H21: 20.67 | I21: 34.87 | J21: 42.04 | K21: 53.18
A22: Employee Cost | G22: 27.76 | H22: 78.85 | I22: 165.62 | J22: 171.3 | K22: 201.16
A23: Selling and admin | G23: 209.72 | H23: 544.54 | I23: 797.44 | J23: 970.96 | K23: 1102.33
A24: Other Expenses | G24: 1369.03 | H24: 4.29 | I24: 24.49 | J24: 15.25 | K24: 26.67
A25: Other Income | G25: 12.1 | H25: 20.84 | I25: -132.18 | J25: 48.6 | K25: 78.73
A26: Depreciation | G26: 1.71 | H26: 6.9 | I26: 24.96 | J26: 30.62 | K26: 45.01
A27: Interest | G27: 0.98 | H27: 3.01 | I27: 6.66 | J27: 9.04 | K27: 12.65
A28: Profit before tax | G28: -1324.61 | H28: 22.43 | I28: -141.04 | J28: 147.17 | K28: 89.61
A29: Tax | G29: 7.61 | H29: 8 | I29: 9.93 | J29: 36.6 | K29: 16.93
A30: Net profit | G30: -1332.22 | H30: 15.72 | I30: -142.81 | J30: 111.82 | K30: 72.69
A31: Dividend Amount
A40: Quarters
A41: Report Date | B41: 45199 | C41: 45291 | D41: 45382 | E41: 45473 | F41: 45565 | G41: 45657 | H41: 45747 | I41: 45838 | J41: 45930 | K41: 46022
A42: Sales | B42: 496.11 | C42: 488.22 | D42: 471.09 | E42: 554.06 | F42: 461.82 | G42: 517.51 | H42: 533.56 | I42: 595.25 | J42: 538.06 | K42: 601.54
A43: Expenses | B43: 455.9 | C43: 453.77 | D43: 437.97 | E43: 507.94 | F43: 492.52 | G43: 491.38 | H43: 506.58 | I43: 549.45 | J43: 490.41 | K43: 536.06
A44: Other Income | B44: 7.08 | C44: 10.97 | D44: 19.05 | E44: 18.72 | F44: 20.02 | G44: 19.22 | H44: 20.78 | I44: 23.89 | J44: 20.14 | K44: 15.88
A45: Depreciation | B45: 6.29 | C45: 8.06 | D45: 9.78 | E45: 9.42 | F45: 10.56 | G45: 12.61 | H45: 12.42 | I45: 10.82 | J45: 11.74 | K45: 11.04
A46: Interest | B46: 1.79 | C46: 2.64 | D46: 3.14 | E46: 3.03 | F46: 3.13 | G46: 3.32 | H46: 3.17 | I46: 3.28 | J46: 3.3 | K46: 3.23
A47: Profit before tax | B47: 39.21 | C47: 34.72 | D47: 39.25 | E47: 52.39 | F47: -24.37 | G47: 29.42 | H47: 32.17 | I47: 55.59 | J47: 52.75 | K47: 67.09
A48: Tax | B48: 9.77 | C48: 8.82 | D48: 8.78 | E48: 12.13 | F48: -5.8 | G48: 3.39 | H48: 7.19 | I48: 14.27 | J48: 13.52 | K48: 16.88
A49: Net profit | B49: 29.44 | C49: 25.9 | D49: 30.48 | E49: 40.26 | F49: -18.58 | G49: 26.02 | H49: 24.98 | I49: 41.33 | J49: 39.23 | K49: 50.2
A50: Operating Profit | B50: 40.21 | C50: 34.45 | D50: 33.12 | E50: 46.12 | F50: -30.7 | G50: 26.13 | H50: 26.98 | I50: 45.8 | J50: 47.65 | K50: 65.48
A55: BALANCE SHEET
A56: Report Date | G56: 44286 | H56: 44651 | I56: 45016 | J56: 45382 | K56: 45747
A57: Equity Share Capital | G57: 0.01 | H57: 0.01 | I57: 136.34 | J57: 324.24 | K57: 325.18
A58: Reserves | G58: -1765.17 | H58: -1087.33 | I58: -1323.37 | J58: 771.03 | K58: 854.65
...
